---
layout: post
title: python线程调试
category: books
catalog: true
published: false
tags:
  - python
time: '2025.05.11 23:28:00'
---
> 客户界面碰到的一个问题，用户代码问题，但是线程池执行就不会抛出错误，但是进程池就会抛出错误。

从官方文档拷贝一个异步线程池执行[示例](https://docs.python.org/3/library/concurrent.futures.html#threadpoolexecu)：
```python
import concurrent.futures
import urllib.request

URLS = ['https://github.com',
        'http://www.foxnews.com/',
        'http://www.cnn.com/',
        'http://europe.wsj.com/',
        'http://www.bbc.co.uk/',
        'http://nonexistent-subdomain.python.org/',
        'http://google.com']

# Retrieve a single page and report the URL and contents
def load_url(url, timeout):
    with urllib.request.urlopen(url, timeout=timeout) as conn:
        return conn.read()

# We can use a with statement to ensure threads are cleaned up promptly
with concurrent.futures.ThreadPoolExecutor(max_workers=5) as executor:
    # Start the load operations and mark each future with its URL
    future_to_url = {executor.submit(load_url, url, 60): url for url in URLS}
    for future in concurrent.futures.as_completed(future_to_url):
        url = future_to_url[future]
        try:
            data = future.result()
        except Exception as exc:
            print('%r generated an exception: %s' % (url, exc))
        else:
            print('%r page is %d bytes' % (url, len(data)))
```
执行该程序的输出结果为：
```shell
'http://www.bbc.co.uk/' page is 662039 bytes
'http://nonexistent-subdomain.python.org/' generated an exception: <urlopen error [Errno -2] Name or service not known>
'http://europe.wsj.com/' generated an exception: HTTP Error 403: Forbidden
'http://www.cnn.com/' page is 3257676 bytes
'http://www.foxnews.com/' page is 746900 bytes
'http://google.com' page is 18238 bytes
'https://github.com' page is 288608 bytes
```

把`load_url()`函数加一个有问题的代码试试是否会报错：
```python
# Retrieve a single page and report the URL and contents
def load_url(url, timeout):
    # 添加的有问题代码，变量未指定
    print(urls)
    with urllib.request.urlopen(url, timeout=timeout) as conn:
        return conn.read()
```
执行修改后的代码输出为：
```
'http://nonexistent-subdomain.python.org/' generated an exception: name 'urls' is not defined
'http://europe.wsj.com/' generated an exception: name 'urls' is not defined
'http://www.cnn.com/' generated an exception: name 'urls' is not defined
'http://www.bbc.co.uk/' generated an exception: name 'urls' is not defined
'https://github.com' generated an exception: name 'urls' is not defined
'http://www.foxnews.com/' generated an exception: name 'urls' is not defined
'http://google.com' generated an exception: name 'urls' is not defined
```
从结果上看，异步线程池执行有语法错误是会抛出来的。

如果使用进程池呢，看看效果会怎样？讲示例中的`concurrent.futures.ThreadPoolExecutor`改成`concurrent.futures.ProcessPoolExecutor`。
实际执行输出是：
```
'https://github.com' generated an exception: name 'urls' is not defined
'http://www.foxnews.com/' generated an exception: name 'urls' is not defined
'http://nonexistent-subdomain.python.org/' generated an exception: name 'urls' is not defined
'http://google.com' generated an exception: name 'urls' is not defined
'http://europe.wsj.com/' generated an exception: name 'urls' is not defined
'http://www.bbc.co.uk/' generated an exception: name 'urls' is not defined
'http://www.cnn.com/' generated an exception: name 'urls' is not defined
```

TODO：奇怪了，客户使用的是python3.9，进程池就会报错，线程池就不会报错，这个问题还是没有复现，和客户代码以及三方库有关？
